Workbook

Sheet Recipe Usage
A1: Recipe Usage — grams per ingredient per batch
A2: One 'cycle' = one batch of each of the four powder mixes, at ONE location. Columbus and Cleveland both run this prep.
A4: Ingredient | B4: Strawberry Skin Renewal | C4: Longevity | D4: Being Brigid 2.0 | E4: Keto Powerhouse 2.0 | F4: Total per cycle
A5: Collagen Peptides Protein, Chocolate | C5: 3000 | E5: 450 | F5: =SUM(B5:E5)
A6: Collagen Peptides Protein, Vanilla | B6: 400 | D6: 900 | F6: =SUM(B6:E6)
A7: Creatine | B7: 500 | C7: 250 | F7: =SUM(B7:E7)
A8: BHB Ketone Powder, Chocolate | E8: 75 | F8: =SUM(B8:E8)
A9: Pitaya / Dragon Fruit Powder | B9: 1000 | F9: =SUM(B9:E9)
A10: Peanut Butter Powder | E10: 1875 | F10: =SUM(B10:E10)
A11: Monkfruit Sugar, Powdered | E11: 750 | F11: =SUM(B11:E11)
A12: Hyaluronic Acid Powder | B12: 200 | F12: =SUM(B12:E12)
A13: Maca Root Powder | D13: 90 | F13: =SUM(B13:E13)
A14: Raw Mesquite Powder | D14: 104 | F14: =SUM(B14:E14)
A15: Chia Seeds | B15: 1200 | D15: 270 | E15: 600 | F15: =SUM(B15:E15)
A16: Sea Moss Powder | B16: 14 | F16: =SUM(B16:E16)
A17: Bovine Colostrum | C17: 100 | F17: =SUM(B17:E17)
A18: Greens w/ PerfectAmino | D18: 90 | F18: =SUM(B18:E18)
A19: Flax Seed, Ground | D19: 35 | F19: =SUM(B19:E19)
A20: Blue Spirulina | C20: 300 | F20: =SUM(B20:E20)
A21: Cocoa Powder | E21: 100 | F21: =SUM(B21:E21)
A22: Allulose Powder | D22: 1800 | F22: =SUM(B22:E22)
A23: Matcha | D23: 54 | F23: =SUM(B23:E23)
A24: Cinnamon, Ground | C24: 50 | F24: =SUM(B24:E24)
A25: BATCH TOTAL (g) | B25: =SUM(B5:B24) | C25: =SUM(C5:C24) | D25: =SUM(D5:D24) | E25: =SUM(E5:E24) | F25: =SUM(F5:F24)
A27: Quantities are from the Powder Prep (Pt. 3) slides dated 9/22/2026.
A28: FLAG: Margin Edge lists Being Brigid flax at 135 g, not 35 g. Slide value used here. See 'Notes & Flags'.

Sheet Order Guide
A1: TownHall — Order Guide
A2: Per location, per cycle. Columbus and Cleveland both run this prep — order for each site.
A3: FILL IN THE YELLOW CELLS: On Hand, then Order Qty. Everything else calculates.
A5: Ingredient | B5: Product / SKU | C5: Vendor | D5: Pack Size | E5: Pack Price | F5: $ / g | G5: Need /cycle (g) | H5: Packs /cycle | I5: On Hand (packs) | J5: Suggested | K5: Order Qty | L5: Ext. Cost | M5: Notes
A6: SMOOTHIE POWDER PREP — AMAZON BUSINESS
A7: Collagen Peptides Protein, Chocolate | B7: Orgain Keto Collagen Protein Powder, Chocolate (14.1 oz) | C7: Amazon | D7: 400 g | E7: 28.25 | F7: =IFERROR(E7/400,"") | G7: ='Recipe Usage'!F5 | H7: =IFERROR(ROUNDUP(G7/400,0),"") | J7: =IFERROR(MAX(0,H7-N(I7)),"") | L7: =IFERROR(N(K7)*E7,0) | M7: 20% off via Subscribe & Save. Margin Edge carries a 19.3 oz pack at a different price — see Notes & Flags.
A8: Collagen Peptides Protein, Vanilla | B8: Orgain Keto Collagen Protein Powder, Vanilla (14.1 oz) | C8: Amazon | D8: 400 g | E8: 28.25 | F8: =IFERROR(E8/400,"") | G8: ='Recipe Usage'!F6 | H8: =IFERROR(ROUNDUP(G8/400,0),"") | J8: =IFERROR(MAX(0,H8-N(I8)),"") | L8: =IFERROR(N(K8)*E8,0) | M8: Strawberry's "vanilla collagen creamer" is THIS product — confirmed in Margin Edge.
A9: Creatine | B9: THORNE Creatine, Micronized Monohydrate, Unflavored, 180 srv | C9: Amazon | D9: 900 g | E9: 84 | F9: =IFERROR(E9/900,"") | G9: ='Recipe Usage'!F7 | H9: =IFERROR(ROUNDUP(G9/900,0),"") | J9: =IFERROR(MAX(0,H9-N(I9)),"") | L9: =IFERROR(N(K9)*E9,0) | M9: Buy the 180-srv tub. 30-srv is 2.6x the cost per gram. Slides say "liposomal" — this is monohydrate.
A10: BHB Ketone Powder, Chocolate | B10: Perfect Keto Base Ketones, Chocolate (8.57 oz) | C10: Amazon | D10: 243 g | E10: 42.74 | F10: =IFERROR(E10/243,"") | G10: ='Recipe Usage'!F8 | H10: =IFERROR(ROUNDUP(G10/243,0),"") | J10: =IFERROR(MAX(0,H10-N(I10)),"") | L10: =IFERROR(N(K10)*E10,0) | M10: Margin Edge uses Perfect Keto NOOTROPIC instead. Confirm which is correct.
A11: Pitaya / Dragon Fruit Powder | B11: Micro Ingredients Organic Dragon Fruit Powder (10 oz) | C11: Amazon | D11: 283 g | E11: 25.34 | F11: =IFERROR(E11/283,"") | G11: ='Recipe Usage'!F9 | H11: =IFERROR(ROUNDUP(G11/283,0),"") | J11: =IFERROR(MAX(0,H11-N(I11)),"") | L11: =IFERROR(N(K11)*E11,0) | M11: Label reads "pink pitaya" — correct product.
A12: Peanut Butter Powder | B12: Micro Ingredients Pure Peanut Butter Powder, 4 lb (no sugar/salt) | C12: Amazon | D12: 1,814 g | E12: 28.41 | F12: =IFERROR(E12/1814,"") | G12: ='Recipe Usage'!F10 | H12: =IFERROR(ROUNDUP(G12/1814,0),"") | J12: =IFERROR(MAX(0,H12-N(I12)),"") | L12: =IFERROR(N(K12)*E12,0) | M12: UNSWEETENED ONLY. Do not substitute Lakanto — Keto has a separate monkfruit line.
A13: Monkfruit Sugar, Powdered | B13: Lakanto Powdered Monk Fruit Sweetener w/ Erythritol, Confectioners, 1 lb | C13: Amazon | D13: 454 g | E13: 16.29 | F13: =IFERROR(E13/454,"") | G13: ='Recipe Usage'!F11 | H13: =IFERROR(ROUNDUP(G13/454,0),"") | J13: =IFERROR(MAX(0,H13-N(I13)),"") | L13: =IFERROR(N(K13)*E13,0)
A14: Hyaluronic Acid Powder | B14: Micro Ingredients Hyaluronic Acid Serum Powder, 100 g | C14: Amazon | D14: 100 g | E14: 34.74 | F14: =IFERROR(E14/100,"") | G14: ='Recipe Usage'!F12 | H14: =IFERROR(ROUNDUP(G14/100,0),"") | J14: =IFERROR(MAX(0,H14-N(I14)),"") | L14: =IFERROR(N(K14)*E14,0) | M14: Recipe hits pack size exactly (2 x 100 g), zero waste.
A15: Maca Root Powder | B15: Micro Ingredients Organic Maca Root Powder, gelatinized, 2 lb | C15: Amazon | D15: 907 g | E15: 23.35 | F15: =IFERROR(E15/907,"") | G15: ='Recipe Usage'!F13 | H15: =IFERROR(ROUNDUP(G15/907,0),"") | J15: =IFERROR(MAX(0,H15-N(I15)),"") | L15: =IFERROR(N(K15)*E15,0) | M15: ~10 batches per bag.
A16: Raw Mesquite Powder | B16: Terrasoul Superfoods Organic Mesquite Powder, 16 oz | C16: Amazon | D16: 454 g | E16: 14.69 | F16: =IFERROR(E16/454,"") | G16: ='Recipe Usage'!F14 | H16: =IFERROR(ROUNDUP(G16/454,0),"") | J16: =IFERROR(MAX(0,H16-N(I16)),"") | L16: =IFERROR(N(K16)*E16,0) | M16: ~4 batches per bag.
A17: Chia Seeds | B17: BBF Organic Chia Seeds, 2 lb jar | C17: Amazon | D17: 907 g | E17: 13.97 | F17: =IFERROR(E17/907,"") | G17: ='Recipe Usage'!F15 | H17: =IFERROR(ROUNDUP(G17/907,0),"") | J17: =IFERROR(MAX(0,H17-N(I17)),"") | L17: =IFERROR(N(K17)*E17,0) | M17: Stay on the 2 lb ($0.44/oz); the 20 oz is $0.48/oz. Margin Edge shows $0.18/oz — see Flags.
A18: Sea Moss Powder | B18: BareOrganics Organic Irish Sea Moss Powder, 8 oz | C18: Amazon | D18: 227 g | E18: 21.97 | F18: =IFERROR(E18/227,"") | G18: ='Recipe Usage'!F16 | H18: =IFERROR(ROUNDUP(G18/227,0),"") | J18: =IFERROR(MAX(0,H18-N(I18)),"") | L18: =IFERROR(N(K18)*E18,0) | M18: ~16 batches per tub.
A19: Bovine Colostrum | B19: Kion Colostrum, Grass-Fed Bovine Powder, 3.39 oz | C19: Amazon | D19: 96 g | E19: 54.95 | F19: =IFERROR(E19/96,"") | G19: ='Recipe Usage'!F17 | H19: =IFERROR(ROUNDUP(G19/96,0),"") | J19: =IFERROR(MAX(0,H19-N(I19)),"") | L19: =IFERROR(N(K19)*E19,0) | M19: Recipe is 100 g vs a 96 g jar — 4 g over forces a 2nd jar. Rounding to 96 g saves $54.95/batch.
A20: Greens w/ PerfectAmino | B20: BodyHealth Greens Enhanced w/ PerfectAmino, Green Apple, 8.61 oz | C20: Amazon | D20: 244 g | E20: 64.17 | F20: =IFERROR(E20/244,"") | G20: ='Recipe Usage'!F18 | H20: =IFERROR(ROUNDUP(G20/244,0),"") | J20: =IFERROR(MAX(0,H20-N(I20)),"") | L20: =IFERROR(N(K20)*E20,0) | M20: Listing has 4 sizes. Standardize on 8.61 oz.
A21: Flax Seed, Ground | B21: Viva Naturals Organic Ground Flaxseed, finely milled, 15 oz | C21: Amazon | D21: 425 g | E21: 11.15 | F21: =IFERROR(E21/425,"") | G21: ='Recipe Usage'!F19 | H21: =IFERROR(ROUNDUP(G21/425,0),"") | J21: =IFERROR(MAX(0,H21-N(I21)),"") | L21: =IFERROR(N(K21)*E21,0) | M21: Business price. Margin Edge shows 135 g per batch, slide says 35 g — confirm.
A22: Blue Spirulina | B22: Micro Ingredients Organic Blue Spirulina (phycocyanin), 2 oz | C22: Amazon | D22: 60 g | E22: 27.26 | F22: =IFERROR(E22/60,"") | G22: ='Recipe Usage'!F20 | H22: =IFERROR(ROUNDUP(G22/60,0),"") | J22: =IFERROR(MAX(0,H22-N(I22)),"") | L22: =IFERROR(N(K22)*E22,0) | M22: Exactly 5 bags, zero waste. 2nd most expensive gram in the program.
A23: Cocoa Powder | B23: ** NO SKU CONFIRMED ** — milled cocoa powder needed | C23: Amazon | D23: — | G23: ='Recipe Usage'!F21 | M23: Cacao NIBS are cafe-side and cannot substitute — they won't pass the sift. Margin Edge has 'Spice, Cocoa Powder' at $1.57/100 g.
A24: SMOOTHIE POWDER PREP — OTHER VENDORS
A25: Allulose Powder | B25: Allulose Powder, 55 lb bulk bag | C25: Hillcrest | D25: 55 lb / 24,948 g | E25: 214.08 | F25: =IFERROR(E25/24948,"") | G25: ='Recipe Usage'!F22 | H25: =IFERROR(ROUNDUP(G25/24948,0),"") | J25: =IFERROR(MAX(0,H25-N(I25)),"") | L25: =IFERROR(N(K25)*E25,0) | M25: ~14 batches per bag. Bulk drop-ship — confirm lead time.
A26: Matcha | B26: Sante Matcha CoffeeHouse Ceremonial, Organic, 250 g | C26: Sante (direct) | D26: 250 g | E26: 74.25 | F26: =IFERROR(E26/250,"") | G26: ='Recipe Usage'!F23 | H26: =IFERROR(ROUNDUP(G26/250,0),"") | J26: =IFERROR(MAX(0,H26-N(I26)),"") | L26: =IFERROR(N(K26)*E26,0) | M26: $74.25/bag net of 38% account discount (list $120). 10-bag lots = $742.50, ~46 batches.
A27: SMOOTHIE LIQUID MIX — recipes confirmed in Margin Edge, usage not yet mapped
A28: Coconut Cream | B28: Nature's Greatest Organic Coconut Cream, no guar gum | C28: Amazon | D28: 12 x 13.5 fl oz | E28: 45.44 | J28: par | L28: =IFERROR(N(K28)*E28,0) | M28: CONFIRMED: Being Brigid Liquid Mix + Fall Coconut Cream (bar). Margin Edge prices it at $0 — data gap.
A29: Almond Milk | B29: Mooala Organic Simple Almond Milk, unsweetened | C29: Amazon | D29: 6 x 32 oz | E29: 36.99 | J29: par | L29: =IFERROR(N(K29)*E29,0) | M29: Liquid Mix component.
A30: Oat Milk Creamer | B30: JOI Instant Oat Milk Creamer Pouch | C30: Amazon | D30: 32 servings | E30: 30.56 | J30: par | L30: =IFERROR(N(K30)*E30,0) | M30: Liquid Mix component.
A31: MCT Oil | B31: Nature's Way Organic MCT Oil | C31: Amazon | D31: 30 fl oz | E31: 20.17 | J31: par | L31: =IFERROR(N(K31)*E31,0) | M31: Liquid Mix component.
A32: Beef Protein, Vanilla | B32: Equip Foods Prime Protein, Vanilla (grass-fed beef) | C32: Amazon | D32: 30 servings | E32: 64.63 | J32: par | L32: =IFERROR(N(K32)*E32,0) | M32: Liquid Mix component.
A33: Cashew Butter | B33: ** NO SKU CONFIRMED ** | C33: Amazon | D33: — | M33: Being Brigid Liquid Mix uses 330 g. Margin Edge prices it at $8.53 — need the purchased SKU.
A34: COCKTAIL / BAR PREP
A35: Chai, Loose Leaf | B35: Davidson's Tea Bulk, Classic Chai | C35: Amazon | D35: 16 oz | E35: 19.12 | J35: par | L35: =IFERROR(N(K35)*E35,0) | M35: CONFIRMED: 'Brewed Chai Tea' bar prep (4 fl oz per 32 oz batch). Margin Edge prices it at $0 — data gap.
A36: Chai Concentrate | B36: Bhakti Chai Tea Concentrate, Unsweetened | C36: Amazon | D36: 2-pack, 16 srv | E36: 19.99 | J36: par | L36: =IFERROR(N(K36)*E36,0) | M36: Second chai format. Confirm both are needed — concentrate vs loose leaf.
A37: Hibiscus Flowers | B37: Organic Hibiscus Flowers, cut & sifted | C37: Amazon | D37: 2 lb | E37: 27.51 | J37: par | L37: =IFERROR(N(K37)*E37,0) | M37: Feeds Hibiscus Cinnamon Simple, Hibiscus Limeade Bulk, Hibiscus Allulose Syrup.
A38: Agave Syrup | B38: Blue Green Organics Raw Blue Agave Syrup | C38: Amazon | D38: 176 oz | E38: 45.59 | J38: par | L38: =IFERROR(N(K38)*E38,0) | M38: Bulk sweetener. Qty 2 last ordered.
A39: Vanilla Bean Paste | B39: Simply Organic Vanilla Bean Paste | C39: Amazon | D39: 4 oz jar | E39: 17.89 | J39: par | L39: =IFERROR(N(K39)*E39,0) | M39: Qty 10 last ordered — high volume for 4 oz jars. Check if a larger pack exists.
A40: Star Anise, Whole | B40: Frontier Co-op Organic Whole Star Anise | C40: Amazon | D40: 1 lb | E40: 33.52 | J40: par | L40: =IFERROR(N(K40)*E40,0) | M40: Qty 4 last ordered.
A41: Pumpkin Pie Spice | B41: Frontier Organic Pumpkin Pie Spice | C41: Amazon | D41: 16 oz | E41: 13.12 | J41: par | L41: =IFERROR(N(K41)*E41,0) | M41: Seasonal. NOT a cinnamon substitute — it's a blend.
...

Sheet Notes & Flags
A1: Notes & Flags — decisions needed before this guide is final
A3: # | B3: Item | C3: Issue | D3: Impact | E3: What's needed
A4: 1 | B4: Cocoa Powder | C4: Keto calls for 100 g cocoa powder. No SKU confirmed. Cacao nibs in order history are cafe-side (acai bowl) and won't pass the fine-mesh sift. | D4: Keto batch cannot be fully costed or ordered. | E4: Confirm a milled cocoa powder SKU. Margin Edge has 'Spice, Cocoa Powder' at $1.57/100 g.
A5: 2 | B5: Bovine Colostrum | C5: Recipe 100 g vs 96 g jar — 4 g (4.2%) over forces a second jar and strands 92 g. | D5: $54.95 per Longevity batch. | E5: Decide: round the recipe to 96 g, or keep 100 g and accept 2 jars.
A6: 3 | B6: Peanut Butter Powder | C6: Recipe 1,875 g vs 1,814 g bag — 61 g (3.4%) over forces a second bag. | D6: $28.41 per Keto batch, plus 1,753 g idle. | E6: Decide: round to 1,814 g (one clean bag) or keep 1,875 g.
A7: 4 | B7: Flax Seed | C7: Slide says 35 g; Margin Edge says 135 g. | D7: Being Brigid batch weight and cost. | E7: Confirm the correct quantity. This guide uses 35 g.
A8: 5 | B8: BHB Ketones | C8: Slide says Base Ketones; Margin Edge uses Perfect Keto NOOTROPIC Brain Support. | D8: Different product at similar price. | E8: Confirm which product Keto actually uses.
A9: 6 | B9: Creatine | C9: Slides say "liposomal creatine"; the product is micronized creatine MONOHYDRATE. | D9: Wording only, if monohydrate is intended. | E9: Reword the slides, or source an actual liposomal product.
A10: 7 | B10: Matcha | C10: This guide uses Sante Ceremonial at $0.297/g. Margin Edge uses a generic matcha at $0.047/g. | D10: ~$13.50 per Being Brigid batch; 6x price difference. | E10: Confirm whether Being Brigid uses Sante or the generic.
A11: 8 | B11: Chocolate Collagen | C11: Amazon Orgain is a 400 g pack at $2.00/oz. Margin Edge carries a 19.3 oz pack: $2.94/oz Columbus, $1.40/oz Cleveland. | D11: Up to $163 per Longevity batch between locations. | E11: Confirm which pack is bought, and why Columbus pays 2.1x Cleveland.
A12: 9 | B12: Chia Seeds | C12: Amazon is $0.44/oz. Margin Edge shows $0.18/oz, bought regularly through 9/8/2026. | D12: This guide may overstate chia by ~2.4x. | E12: Confirm whether chia comes from Amazon or a foodservice vendor.
A13: 10 | B13: Two locations | C13: Columbus and Cleveland both run this prep. This sheet is ONE location. | D13: Doubling gives ~2x cost, but several packs carry 10-46 batches of runway. | E13: Decide split vs duplicate: per site for fast movers, order once and split for 4+ batch runway.
A14: 11 | B14: Batch frequency | C14: Unknown. | D14: Cannot convert per-cycle quantities into a reorder cadence or par levels. | E14: Provide how often each batch is run, per location.
A15: 12 | B15: Cocktail usage | C15: Cocktail, cafe and liquid-mix lines have no grams-per-cycle mapped, so they show "par" instead of a suggested qty. | D15: Those lines must be ordered by eye until mapped. | E15: Margin Edge has 23 'TH - Bar Prep' recipes (see Bar Prep Reference tab). Map products to them to make these lines calculate.
... A19: 16 | B19: Coconut Sugar | C19: $14.26 listed for a 6 x 1 lb pack is unusually low. | D19: Could be per-bag, making the line 6x this cost. | E19: Verify pack vs unit pricing before ordering.

Sheet Bar Prep Reference
A1: Bar Prep Recipes in Margin Edge (TownHall - Columbus)
A2: Pulled 2026-09-29. These are the 23 'TH - Bar Prep' recipes. Mapping order-guide products to these will let the cocktail lines calculate instead of ordering to par.
A4: Recipe ID | B4: Recipe | C4: Cost | D4: Yield | E4: Notes
A5: 333495432 | B5: Against Doctor's Orders #1 - Batch | C5: 82.48 | D5: 128 fl oz
A6: 333490741 | B6: Apple Cinnamon Infused Bacardi | C6: 28.8 | D6: 24.5 fl oz | E6: Spirit infusion — liquor vendor
A7: 333478898 | B7: At Dawn They Sleep - Batch | C7: 25.48 | D7: 34 fl oz
A8: 328403264 | B8: Bloody Mary Spice Blend | C8: 1 | D8: 8.3 tbsp
A9: 333469888 | B9: Brewed Chai Tea | C9: 12.91 | D9: 32 fl oz | E9: USES: Loose Leaf Chai 4 fl oz, Water 32 fl oz, Honey 2 fl oz
A10: 333468674 | B10: Channel Orange - Batched | C10: 30.78 | D10: 32 fl oz
A11: 333464610 | B11: Crash Course - Batched | C11: 26.19 | D11: 32 fl oz
A12: 333504278 | B12: Dragonwell Infused OYO Vodka | C12: 16.45 | D12: 24 fl oz | E12: Spirit infusion — liquor vendor
A13: 333500998 | B13: Espresso Martini Mix | C13: 3.8 | D13: 25.4 fl oz
A14: 333492968 | B14: Fall Coconut Cream | C14: 18.14 | D14: 72 fl oz | E14: USES: Coconut Cream 15 fl oz, Coconut Milk 13.5 fl oz, pineapple, allspice, cinnamon, nutmeg, pom molasses
A15: 333473987 | B15: Grapefruit Infused Patron | C15: 0.06 | D15: 1 bottle | E15: Spirit infusion — cost looks wrong ($0.06)
A16: 333504038 | B16: Green Goddess - Batch | C16: 18.55 | D16: 33 fl oz
A17: 525737107 | B17: Heaven or LV BIZ - TH | C17: 7.28 | D17: 4.5 fl oz
A18: 333481247 | B18: Jammy Pom Juice | C18: 8.2 | D18: 35 fl oz
A19: 333486093 | B19: Lemony Lemon Curd Juice | C19: 2.42 | D19: 25 fl oz
A20: 333470550 | B20: Pear Chai Tea | C20: 8.88 | D20: 34 fl oz | E20: USES: Pear Simple Syrup, Brewed Chai Tea, Lemon Juice
A21: 333504478 | B21: Spicy Cucumber Juice | C21: 7.18 | D21: 33.25 fl oz
A22: 333485862 | B22: Strawberry Infused Bombay Bramble | C22: 22.33 | D22: 24.5 fl oz | E22: Spirit infusion — liquor vendor
A23: 333486498 | B23: Strawberry Kush - Batch | C23: 33.51 | D23: 40 fl oz
A24: 333498796 | B24: Sweetheart Infused Vodka | C24: 19.72 | D24: 27 fl oz | E24: Spirit infusion — liquor vendor
A25: 333504145 | B25: Syrup, Arugula | C25: 2.8 | D25: 12 fl oz
A26: 333468799 | B26: Syrup, Pear Simple | C26: 8.47 | D26: 32 fl oz
A27: 333460643 | B27: Syrup, Queen of Earl | C27: 6.3 | D27: 16 fl oz
A29: Only 3 of the 23 had their ingredient lists pulled (noted above). Hibiscus syrups sit under 'TH - Prep', not 'TH - Bar Prep'.
